<?xml version="1.0"?>
<robot name="olaf">
    <link name="base_link">
        <visual>
            <geometry>
                <box size="0.4 0.4 0.2"/>
            </geometry>
            <material name="silver">
                <color rgba="0.75 0.75 0.75 1"/>
            </material>
        </visual>
        <collision>
            <geometry>
                <box size="0.4 0.4 0.2"/>
            </geometry>
        </collision>
        <inertial>
            <origin xyz="0.0 0.0 0.0" rpy="0.0 0.0 0.0"/>
            <mass value="10.0"/>
            <inertia ixx="0.03" ixy="0.03" ixz="0.03" iyy="0.0" iyz="0.0" izz="0.0"/>
        </inertial>
    </link>
    <link name="left_wheel">
        <inertial>
            <origin xyz="0.0 0.0 0.0" rpy="0.0 0.0 0.0"/>
            <mass value="1.0"/>
            <inertia ixx="5.15e-5" ixy="5.15e-5" ixz="6.15e-5" iyy="0.0" iyz="0.0" izz="0.0"/>
        </inertial>
        <visual name="">
            <origin xyz="0.0 0.0 0.0" rpy="1.57 0.0 0.0"/>
            <geometry>
                <cylinder radius="0.08" length="0.05"/>
            </geometry>
            <material name="black">
                <color rgba="0.0 0.0 0.0 1.0"/>
            </material>
        </visual>
        <collision>
            <origin xyz="0.0 0.0 0.0" rpy="1.57 0.0 0.0"/>
            <geometry>
                <cylinder radius="0.08" length="0.05"/>
            </geometry>
        </collision>
    </link>
    <joint name="left_wheel_joint" type="continuous">
        <origin xyz="0.1 0.25 -0.05" rpy="0.0 0.0 0.0"/>
        <parent link="base_link"/>
        <child link="left_wheel"/>
        <axis xyz="0.0 1 0"/>
    </joint>

    <link name="right_wheel">
        <inertial>
            <origin xyz="0.0 0.0 0.0" rpy="0.0 0.0 0.0"/>
            <mass value="1.0"/>
            <inertia ixx="5.15e-5" ixy="5.15e-5" ixz="6.15e-5" iyy="0.0" iyz="0.0" izz="0.0"/>
        </inertial>
        <visual name="">
            <origin xyz="0.0 0.0 0.0" rpy="1.57 0.0 0.0"/>
            <geometry>
                <cylinder radius="0.08" length="0.05"/>
            </geometry>
            <material name="black">
                <color rgba="0 0 0 1"/>
            </material>
        </visual>
        <collision>
            <origin xyz="0.0 0.0 0.0" rpy="1.57 0.0 0.0"/>
            <geometry>
                <cylinder radius="0.08" length="0.05"/>
            </geometry>
        </collision>
    </link>
    <joint name="right_wheel_joint" type="continuous">
        <origin xyz="0.1 -0.25 -0.05" rpy="0.0 0.0 0.0"/>
        <parent link="base_link"/>
        <child link="right_wheel"/>
        <axis xyz="0.0 1 0"/>
    </joint>

    <link name="right_back_wheel">
        <inertial>
            <origin xyz="0.0 0.0 0.0" rpy="0.0 0.0 0.0"/>
            <mass value="1.0"/>
            <inertia ixx="5.15e-5" ixy="5.15e-5" ixz="6.15e-5" iyy="0.0" iyz="0.0" izz="0.0"/>
        </inertial>
        <visual name="">
            <origin xyz="0.0 0.0 0.0" rpy="0.0 0.0 0.0"/>
            <geometry>
                <sphere radius="0.02"/>
            </geometry>
            <material name="black">
                <texture filename=""/>
            </material>
        </visual>
        <collision>
            <origin xyz="0.0 0.0 0.0" rpy="0.0 0.0 0.0"/>
            <geometry>
                <sphere radius="0.02"/>
            </geometry>
        </collision>
    </link>
    <joint name="right_back_wheel_joint" type="continuous">
        <origin xyz="-0.18 -0.18 -0.11" rpy="0.0 0.0 0.0"/>
        <parent link="base_link"/>
        <child link="right_back_wheel"/>
        <axis xyz="1 1 1"/>
    </joint>
    <link name="left_back_wheel">
        <inertial>
            <origin xyz="0.0 0.0 0.0" rpy="0.0 0.0 0.0"/>
            <mass value="1.0"/>
            <inertia ixx="5.15e-5" ixy="5.15e-5" ixz="6.15e-5" iyy="0.0" iyz="0.0" izz="0.0"/>
        </inertial>
        <visual name="">
            <origin xyz="0.0 0.0 0.0" rpy="0.0 0.0 0.0"/>
            <geometry>
                <sphere radius="0.02"/>
            </geometry>
            <material name="black">
                <texture filename=""/>
            </material>
        </visual>
        <collision>
            <origin xyz="0.0 0.0 0.0" rpy="0.0 0.0 0.0"/>
            <geometry>
                <sphere radius="0.02"/>
            </geometry>
        </collision>
    </link>
    <joint name="left_back_wheel_joint" type="continuous">
        <origin xyz="-0.18 0.18 -0.11" rpy="0.0 0.0 0.0"/>
        <parent link="base_link"/>
        <child link="left_back_wheel"/>
        <axis xyz="1 1 1"/>
    </joint>
    <gazebo>
        <plugin name="differential_drive_controller" filename="libgazebo_ros_diff_drive.so">

            <!-- Plugin update rate in Hz -->
            <updateRate>50</updateRate>

            <!-- Name of left joint, defaults to `left_joint` -->
            <leftJoint>left_wheel_joint</leftJoint>

            <!-- Name of right joint, defaults to `right_joint` -->
            <rightJoint>right_wheel_joint</rightJoint>

            <!-- The distance from the center of one wheel to the other, in meters, defaults to 0.34 m -->
            <wheelSeparation>0.5</wheelSeparation>

            <!-- Diameter of the wheels, in meters, defaults to 0.15 m -->
            <wheelDiameter>0.160</wheelDiameter>

            <!-- Wheel acceleration, in rad/s^2, defaults to 0.0 rad/s^2 -->
            <wheelAcceleration>1.0</wheelAcceleration>

            <!-- Maximum torque which the wheels can produce, in Nm, defaults to 5 Nm -->
            <!--BA_Brauner S.25 definiert-->
            <wheelTorque>6</wheelTorque>

            <!-- Topic to receive geometry_msgs/Twist message commands, defaults to `cmd_vel` -->
            <commandTopic>cmd_vel</commandTopic>

            <!-- Topic to publish nav_msgs/Odometry messages, defaults to `odom` -->
            <odometryTopic>odom</odometryTopic>

            <!-- Odometry frame, defaults to `odom` -->
            <odometryFrame>odom</odometryFrame>

            <!-- Robot frame to calculate odometry from, defaults to `base_footprint` -->
            <robotBaseFrame>base_link</robotBaseFrame>

            <!-- Odometry source, 0 for ENCODER, 1 for WORLD, defaults to WORLD -->
            <odometrySource>1</odometrySource>

            <!-- Set to true to publish transforms for the wheel links, defaults to false -->
            <publishWheelTF>true</publishWheelTF>

            <!-- Set to true to publish transforms for the odometry, defaults to true -->
            <publishOdom>true</publishOdom>

            <!-- Set to true to publish sensor_msgs/JointState on /joint_states for the wheel joints, defaults to false -->
            <publishWheelJointState>true</publishWheelJointState>

            <!-- Set to true to swap right and left wheels, defaults to true -->
            <legacyMode>false</legacyMode>
        </plugin>
    </gazebo>

    <gazebo reference="left_wheel_joint">
        <mu1 value="200.0"/>
        <mu2 value="100.0"/>
        <kp value="10000000.0" />
        <kd value="1.0" />
        <material>Gazebo/Grey</material>
    </gazebo>
    <gazebo reference="right_wheel_joint">
        <mu1 value="200.0"/>
        <mu2 value="100.0"/>
        <kp value="10000000.0" />
        <kd value="1.0" />
        <material>Gazebo/Grey</material>
    </gazebo>
    <gazebo>
        <plugin name="joint_state_publisher" filename="libgazebo_ros_joint_state_publisher.so">
            <jointName>left_back_wheel_joint, right_back_wheel_joint</jointName>
        </plugin>
    </gazebo>
</robot>
